Workbook

Sheet Leia-me
B2: Porsche · Vendas Brasil
B3: Base analítica de 100 vendas por versão, ano, cidade, estado e forma de pagamento
B5: ⚠ Base simulada para fins de demonstração — não representa vendas reais da Porsche Brasil.
B7: Abas
B8: Vendas | C8: Uma linha por venda (fato). Valor calculado por fórmula a partir das Premissas.
B9: Resumo | C9: Indicadores e totais por linha, segmento, propulsão, estado, região, ano e pagamento (fórmulas).
B10: Premissas | C10: Preços de entrada por linha no Brasil. Células amarelas são editáveis e recalculam toda a base.
B11: Dicionário | C11: Descrição, tipo e regra de cada coluna da aba Vendas.
B13: Metodologia
B14: Origem | C14: Tabela de demonstração com 100 vendas (EUA, US$) do dashboard original do repositório.
B15: Valores em R$ | C15: Preço de entrada da linha no Brasil × fator de versão (proporção de preço da versão sobre a versão mais barata da mesma linha na tabela original), arredondado a R$ 1.000.
B16: Localização | C16: Cidades substituídas pelas 13 cidades com Porsche Center no Brasil (14 lojas), com peso maior para mercados maiores (São Paulo).
B17: Pagamento | C17: Adaptado ao Brasil: Wire Transfer→Pix, Bank Transfer→TED, ACH→Boleto, Cash→Dinheiro, Financing→Financiamento, Lease→Leasing.
B18: Campos derivados | C18: Segmento (Esportivo, Sedã / GT, SUV), Propulsão (Combustão, Híbrido, Elétrico) e Faixa de preço.
B20: Fontes
B21: Preços de entrada | C21: Vrum / Estado de Minas, “Porsche no Brasil: preços atualizados dos modelos”, fev/2026 — https://www.vrum.com.br/mercado/2026/02/7348831-porsche-no-brasil-precos-atualizados-dos-modelos-e-o-mais-desejado.html
B22: Rede de concessionárias | C22: Porsche Brasil — https://www.porsche.com/brazil/pt/aboutporsche/porschebrasil
B23: Tabela original | C23: https://github.com/marcos7ut/dashboard_porche-sales (versão anterior do index.html)

Sheet Resumo
B2: Resumo executivo
B3: Todos os números são fórmulas sobre a aba Vendas
B6: Receita total | C6: =SUM(Vendas!L2:L101) -> 130989000
B7: Unidades vendidas | C7: =COUNTA(Vendas!A2:A101) -> 100
B8: Ticket médio | C8: =IF(C7=0,0,C6/C7) -> 1309890
B9: Mediana do preço | C9: =MEDIAN(Vendas!L2:L101) -> 1076500
B10: Maior venda | C10: =MAX(Vendas!L2:L101) -> 2916000
B11: Versões diferentes | C11: =SUMPRODUCT(1/COUNTIF(Vendas!B2:B101,Vendas!B2:B101)) -> 40
B14: Por linha | H14: Por estado (UF)
B15: Linha | C15: Unid. | D15: Receita (R$) | E15: % receita | F15: Ticket médio | H15: UF | I15: Unid. | J15: Receita (R$) | K15: % receita | L15: Ticket médio
B16: 911 | C16: =COUNTIF(Vendas!$C$2:$C$101,B16) -> 23 | D16: =SUMIF(Vendas!$C$2:$C$101,B16,Vendas!$L$2:$L$101) -> 43482000 | E16: =IF($C$6=0,0,D16/$C$6) -> 0.33195154 | F16: =IF(C16=0,0,D16/C16) -> 1890521.7 | H16: SP | I16: =COUNTIF(Vendas!$H$2:$H$101,H16) -> 39 | J16: =SUMIF(Vendas!$H$2:$H$101,H16,Vendas!$L$2:$L$101) -> 49654000 | K16: =IF($C$6=0,0,J16/$C$6) -> 0.37907 | L16: =IF(I16=0,0,J16/I16) -> 1273179.5
B17: Cayenne | C17: =COUNTIF(Vendas!$C$2:$C$101,B17) -> 18 | D17: =SUMIF(Vendas!$C$2:$C$101,B17,Vendas!$L$2:$L$101) -> 21924000 | E17: =IF($C$6=0,0,D17/$C$6) -> 0.16737283 | F17: =IF(C17=0,0,D17/C17) -> 1218000 | H17: RJ | I17: =COUNTIF(Vendas!$H$2:$H$101,H17) -> 10 | J17: =SUMIF(Vendas!$H$2:$H$101,H17,Vendas!$L$2:$L$101) -> 12220000 | K17: =IF($C$6=0,0,J17/$C$6) -> 0.093290276 | L17: =IF(I17=0,0,J17/I17) -> 1222000
B18: Panamera | C18: =COUNTIF(Vendas!$C$2:$C$101,B18) -> 14 | D18: =SUMIF(Vendas!$C$2:$C$101,B18,Vendas!$L$2:$L$101) -> 20120000 | E18: =IF($C$6=0,0,D18/$C$6) -> 0.15360068 | F18: =IF(C18=0,0,D18/C18) -> 1437142.9 | H18: MG | I18: =COUNTIF(Vendas!$H$2:$H$101,H18) -> 8 | J18: =SUMIF(Vendas!$H$2:$H$101,H18,Vendas!$L$2:$L$101) -> 9848000 | K18: =IF($C$6=0,0,J18/$C$6) -> 0.075181886 | L18: =IF(I18=0,0,J18/I18) -> 1231000
B19: Taycan | C19: =COUNTIF(Vendas!$C$2:$C$101,B19) -> 16 | D19: =SUMIF(Vendas!$C$2:$C$101,B19,Vendas!$L$2:$L$101) -> 16977000 | E19: =IF($C$6=0,0,D19/$C$6) -> 0.1296063 | F19: =IF(C19=0,0,D19/C19) -> 1061062.5 | H19: DF | I19: =COUNTIF(Vendas!$H$2:$H$101,H19) -> 8 | J19: =SUMIF(Vendas!$H$2:$H$101,H19,Vendas!$L$2:$L$101) -> 9567000 | K19: =IF($C$6=0,0,J19/$C$6) -> 0.073036667 | L19: =IF(I19=0,0,J19/I19) -> 1195875
B20: 718 | C20: =COUNTIF(Vendas!$C$2:$C$101,B20) -> 12 | D20: =SUMIF(Vendas!$C$2:$C$101,B20,Vendas!$L$2:$L$101) -> 15308000 | E20: =IF($C$6=0,0,D20/$C$6) -> 0.11686477 | F20: =IF(C20=0,0,D20/C20) -> 1275666.7 | H20: PR | I20: =COUNTIF(Vendas!$H$2:$H$101,H20) -> 7 | J20: =SUMIF(Vendas!$H$2:$H$101,H20,Vendas!$L$2:$L$101) -> 9116000 | K20: =IF($C$6=0,0,J20/$C$6) -> 0.06959363 | L20: =IF(I20=0,0,J20/I20) -> 1302285.7
B21: Macan | C21: =COUNTIF(Vendas!$C$2:$C$101,B21) -> 17 | D21: =SUMIF(Vendas!$C$2:$C$101,B21,Vendas!$L$2:$L$101) -> 13178000 | E21: =IF($C$6=0,0,D21/$C$6) -> 0.10060387 | F21: =IF(C21=0,0,D21/C21) -> 775176.47 | H21: RS | I21: =COUNTIF(Vendas!$H$2:$H$101,H21) -> 7 | J21: =SUMIF(Vendas!$H$2:$H$101,H21,Vendas!$L$2:$L$101) -> 9393000 | K21: =IF($C$6=0,0,J21/$C$6) -> 0.071708311 | L21: =IF(I21=0,0,J21/I21) -> 1341857.1
H22: SC | I22: =COUNTIF(Vendas!$H$2:$H$101,H22) -> 6 | J22: =SUMIF(Vendas!$H$2:$H$101,H22,Vendas!$L$2:$L$101) -> 6898000 | K22: =IF($C$6=0,0,J22/$C$6) -> 0.05266091 | L22: =IF(I22=0,0,J22/I22) -> 1149666.7
B23: Por segmento | H23: GO | I23: =COUNTIF(Vendas!$H$2:$H$101,H23) -> 5 | J23: =SUMIF(Vendas!$H$2:$H$101,H23,Vendas!$L$2:$L$101) -> 8093000 | K23: =IF($C$6=0,0,J23/$C$6) -> 0.061783814 | L23: =IF(I23=0,0,J23/I23) -> 1618600
B24: Segmento | C24: Unid. | D24: Receita (R$) | E24: % receita | F24: Ticket médio | H24: PE | I24: =COUNTIF(Vendas!$H$2:$H$101,H24) -> 4 | J24: =SUMIF(Vendas!$H$2:$H$101,H24,Vendas!$L$2:$L$101) -> 6254000 | K24: =IF($C$6=0,0,J24/$C$6) -> 0.047744467 | L24: =IF(I24=0,0,J24/I24) -> 1563500
B25: Esportivo | C25: =COUNTIF(Vendas!$D$2:$D$101,B25) -> 35 | D25: =SUMIF(Vendas!$D$2:$D$101,B25,Vendas!$L$2:$L$101) -> 58790000 | E25: =IF($C$6=0,0,D25/$C$6) -> 0.44881631 | F25: =IF(C25=0,0,D25/C25) -> 1679714.3 | H25: BA | I25: =COUNTIF(Vendas!$H$2:$H$101,H25) -> 3 | J25: =SUMIF(Vendas!$H$2:$H$101,H25,Vendas!$L$2:$L$101) -> 4620000 | K25: =IF($C$6=0,0,J25/$C$6) -> 0.035270137 | L25: =IF(I25=0,0,J25/I25) -> 1540000
B26: Sedã / GT | C26: =COUNTIF(Vendas!$D$2:$D$101,B26) -> 30 | D26: =SUMIF(Vendas!$D$2:$D$101,B26,Vendas!$L$2:$L$101) -> 37097000 | E26: =IF($C$6=0,0,D26/$C$6) -> 0.28320699 | F26: =IF(C26=0,0,D26/C26) -> 1236566.7 | H26: CE | I26: =COUNTIF(Vendas!$H$2:$H$101,H26) -> 3 | J26: =SUMIF(Vendas!$H$2:$H$101,H26,Vendas!$L$2:$L$101) -> 5326000 | K26: =IF($C$6=0,0,J26/$C$6) -> 0.040659903 | L26: =IF(I26=0,0,J26/I26) -> 1775333.3
B27: SUV | C27: =COUNTIF(Vendas!$D$2:$D$101,B27) -> 35 | D27: =SUMIF(Vendas!$D$2:$D$101,B27,Vendas!$L$2:$L$101) -> 35102000 | E27: =IF($C$6=0,0,D27/$C$6) -> 0.2679767 | F27: =IF(C27=0,0,D27/C27) -> 1002914.3
H28: Por região
B29: Por propulsão | H29: Região | I29: Unid. | J29: Receita (R$) | K29: % receita | L29: Ticket médio
B30: Propulsão | C30: Unid. | D30: Receita (R$) | E30: % receita | F30: Ticket médio | H30: Sudeste | I30: =COUNTIF(Vendas!$I$2:$I$101,H30) -> 57 | J30: =SUMIF(Vendas!$I$2:$I$101,H30,Vendas!$L$2:$L$101) -> 71722000 | K30: =IF($C$6=0,0,J30/$C$6) -> 0.54754216 | L30: =IF(I30=0,0,J30/I30) -> 1258280.7
B31: Combustão | C31: =COUNTIF(Vendas!$E$2:$E$101,B31) -> 74 | D31: =SUMIF(Vendas!$E$2:$E$101,B31,Vendas!$L$2:$L$101) -> 103600000 | E31: =IF($C$6=0,0,D31/$C$6) -> 0.79090611 | F31: =IF(C31=0,0,D31/C31) -> 1400000 | H31: Sul | I31: =COUNTIF(Vendas!$I$2:$I$101,H31) -> 20 | J31: =SUMIF(Vendas!$I$2:$I$101,H31,Vendas!$L$2:$L$101) -> 25407000 | K31: =IF($C$6=0,0,J31/$C$6) -> 0.19396285 | L31: =IF(I31=0,0,J31/I31) -> 1270350
B32: Híbrido | C32: =COUNTIF(Vendas!$E$2:$E$101,B32) -> 6 | D32: =SUMIF(Vendas!$E$2:$E$101,B32,Vendas!$L$2:$L$101) -> 6866000 | E32: =IF($C$6=0,0,D32/$C$6) -> 0.052416615 | F32: =IF(C32=0,0,D32/C32) -> 1144333.3 | H32: Centro-Oeste | I32: =COUNTIF(Vendas!$I$2:$I$101,H32) -> 13 | J32: =SUMIF(Vendas!$I$2:$I$101,H32,Vendas!$L$2:$L$101) -> 17660000 | K32: =IF($C$6=0,0,J32/$C$6) -> 0.13482048 | L32: =IF(I32=0,0,J32/I32) -> 1358461.5
B33: Elétrico | C33: =COUNTIF(Vendas!$E$2:$E$101,B33) -> 20 | D33: =SUMIF(Vendas!$E$2:$E$101,B33,Vendas!$L$2:$L$101) -> 20523000 | E33: =IF($C$6=0,0,D33/$C$6) -> 0.15667728 | F33: =IF(C33=0,0,D33/C33) -> 1026150 | H33: Nordeste | I33: =COUNTIF(Vendas!$I$2:$I$101,H33) -> 10 | J33: =SUMIF(Vendas!$I$2:$I$101,H33,Vendas!$L$2:$L$101) -> 16200000 | K33: =IF($C$6=0,0,J33/$C$6) -> 0.12367451 | L33: =IF(I33=0,0,J33/I33) -> 1620000
B35: Por faixa de preço | H35: Por ano
B36: Faixa de preço | C36: Unid. | D36: Receita (R$) | E36: % receita | F36: Ticket médio | H36: Ano | I36: Unid. | J36: Receita (R$) | K36: % receita | L36: Ticket médio
B37: Até R$ 1 mi | C37: =COUNTIF(Vendas!$M$2:$M$101,B37) -> 42 | D37: =SUMIF(Vendas!$M$2:$M$101,B37,Vendas!$L$2:$L$101) -> 35974000 | E37: =IF($C$6=0,0,D37/$C$6) -> 0.27463375 | F37: =IF(C37=0,0,D37/C37) -> 856523.81 | H37: 2020 | I37: =COUNTIF(Vendas!$F$2:$F$101,H37) -> 4 | J37: =SUMIF(Vendas!$F$2:$F$101,H37,Vendas!$L$2:$L$101) -> 4753000 | K37: =IF($C$6=0,0,J37/$C$6) -> 0.03628549 | L37: =IF(I37=0,0,J37/I37) -> 1188250
B38: R$ 1–1,5 mi | C38: =COUNTIF(Vendas!$M$2:$M$101,B38) -> 29 | D38: =SUMIF(Vendas!$M$2:$M$101,B38,Vendas!$L$2:$L$101) -> 34835000 | E38: =IF($C$6=0,0,D38/$C$6) -> 0.26593836 | F38: =IF(C38=0,0,D38/C38) -> 1201206.9 | H38: 2021 | I38: =COUNTIF(Vendas!$F$2:$F$101,H38) -> 12 | J38: =SUMIF(Vendas!$F$2:$F$101,H38,Vendas!$L$2:$L$101) -> 9687000 | K38: =IF($C$6=0,0,J38/$C$6) -> 0.073952775 | L38: =IF(I38=0,0,J38/I38) -> 807250
B39: R$ 1,5–2 mi | C39: =COUNTIF(Vendas!$M$2:$M$101,B39) -> 14 | D39: =SUMIF(Vendas!$M$2:$M$101,B39,Vendas!$L$2:$L$101) -> 24133000 | E39: =IF($C$6=0,0,D39/$C$6) -> 0.18423684 | F39: =IF(C39=0,0,D39/C39) -> 1723785.7 | H39: 2022 | I39: =COUNTIF(Vendas!$F$2:$F$101,H39) -> 16 | J39: =SUMIF(Vendas!$F$2:$F$101,H39,Vendas!$L$2:$L$101) -> 17278000 | K39: =IF($C$6=0,0,J39/$C$6) -> 0.13190421 | L39: =IF(I39=0,0,J39/I39) -> 1079875
B40: Acima de R$ 2 mi | C40: =COUNTIF(Vendas!$M$2:$M$101,B40) -> 15 | D40: =SUMIF(Vendas!$M$2:$M$101,B40,Vendas!$L$2:$L$101) -> 36047000 | E40: =IF($C$6=0,0,D40/$C$6) -> 0.27519105 | F40: =IF(C40=0,0,D40/C40) -> 2403133.3 | H40: 2023 | I40: =COUNTIF(Vendas!$F$2:$F$101,H40) -> 19 | J40: =SUMIF(Vendas!$F$2:$F$101,H40,Vendas!$L$2:$L$101) -> 22206000 | K40: =IF($C$6=0,0,J40/$C$6) -> 0.16952569 | L40: =IF(I40=0,0,J40/I40) -> 1168736.8
H41: 2024 | I41: =COUNTIF(Vendas!$F$2:$F$101,H41) -> 29 | J41: =SUMIF(Vendas!$F$2:$F$101,H41,Vendas!$L$2:$L$101) -> 48753000 | K41: =IF($C$6=0,0,J41/$C$6) -> 0.37219156 | L41: =IF(I41=0,0,J41/I41) -> 1681137.9
H42: 2025 | I42: =COUNTIF(Vendas!$F$2:$F$101,H42) -> 16 | J42: =SUMIF(Vendas!$F$2:$F$101,H42,Vendas!$L$2:$L$101) -> 21598000 | K42: =IF($C$6=0,0,J42/$C$6) -> 0.16488407 | L42: =IF(I42=0,0,J42/I42) -> 1349875
H43: 2026 | I43: =COUNTIF(Vendas!$F$2:$F$101,H43) -> 4 | J43: =SUMIF(Vendas!$F$2:$F$101,H43,Vendas!$L$2:$L$101) -> 6714000 | K43: =IF($C$6=0,0,J43/$C$6) -> 0.051256212 | L43: =IF(I43=0,0,J43/I43) -> 1678500
H45: Por forma de pagamento
H46: Forma de pagamento | I46: Unid. | J46: Receita (R$) | K46: % receita | L46: Ticket médio
H47: Boleto | I47: =COUNTIF(Vendas!$J$2:$J$101,H47) -> 4 | J47: =SUMIF(Vendas!$J$2:$J$101,H47,Vendas!$L$2:$L$101) -> 4197000 | K47: =IF($C$6=0,0,J47/$C$6) -> 0.032040858 | L47: =IF(I47=0,0,J47/I47) -> 1049250
...

Sheet Vendas
A1: ID | B1: Versão | C1: Linha | D1: Segmento | E1: Propulsão | F1: Ano | G1: Cidade | H1: UF | I1: Região | J1: Forma de pagamento | K1: Fator de versão | L1: Valor (R$) | M1: Faixa de preço
A2: VND-001 | B2: 718 Cayman | C2: 718 | D2: Esportivo | E2: Combustão | F2: 2022 | G2: Campinas | H2: SP | I2: Sudeste | J2: Cartão de crédito | K2: 1.1373 | L2: =ROUND(INDEX(Premissas!$C$6:$C$11,MATCH(C2,Premissas!$B$6:$B$11,0))*K2,-3) -> 933000 | M2: =IF(L2<1000000,"Até R$ 1 mi",IF(L2<1500000,"R$ 1–1,5 mi",IF(L2<2000000,"R$ 1,5–2 mi","Acima de R$ 2 mi"))) -> Até R$ 1 mi
A3: VND-002 | B3: 911 Turbo S | C3: 911 | D3: Esportivo | E3: Combustão | F3: 2024 | G3: Recife | H3: PE | I3: Nordeste | J3: Pix | K3: 2.4403 | L3: =ROUND(INDEX(Premissas!$C$6:$C$11,MATCH(C3,Premissas!$B$6:$B$11,0))*K3,-3) -> 2391000 | M3: =IF(L3<1000000,"Até R$ 1 mi",IF(L3<1500000,"R$ 1–1,5 mi",IF(L3<2000000,"R$ 1,5–2 mi","Acima de R$ 2 mi"))) -> Acima de R$ 2 mi
A4: VND-003 | B4: Cayenne Coupe | C4: Cayenne | D4: SUV | E4: Combustão | F4: 2023 | G4: Brasília | H4: DF | I4: Centro-Oeste | J4: Financiamento | K4: 1.4681 | L4: =ROUND(INDEX(Premissas!$C$6:$C$11,MATCH(C4,Premissas!$B$6:$B$11,0))*K4,-3) -> 1189000 | M4: =IF(L4<1000000,"Até R$ 1 mi",IF(L4<1500000,"R$ 1–1,5 mi",IF(L4<2000000,"R$ 1,5–2 mi","Acima de R$ 2 mi"))) -> R$ 1–1,5 mi
A5: VND-004 | B5: Macan S | C5: Macan | D5: SUV | E5: Combustão | F5: 2021 | G5: Belo Horizonte | H5: MG | I5: Sudeste | J5: Dinheiro | K5: 1.1698 | L5: =ROUND(INDEX(Premissas!$C$6:$C$11,MATCH(C5,Premissas!$B$6:$B$11,0))*K5,-3) -> 678000 | M5: =IF(L5<1000000,"Até R$ 1 mi",IF(L5<1500000,"R$ 1–1,5 mi",IF(L5<2000000,"R$ 1,5–2 mi","Acima de R$ 2 mi"))) -> Até R$ 1 mi
A6: VND-005 | B6: Taycan 4S | C6: Taycan | D6: Sedã / GT | E6: Elétrico | F6: 2024 | G6: Fortaleza | H6: CE | I6: Nordeste | J6: TED | K6: 1.0351 | L6: =ROUND(INDEX(Premissas!$C$6:$C$11,MATCH(C6,Premissas!$B$6:$B$11,0))*K6,-3) -> 880000 | M6: =IF(L6<1000000,"Até R$ 1 mi",IF(L6<1500000,"R$ 1–1,5 mi",IF(L6<2000000,"R$ 1,5–2 mi","Acima de R$ 2 mi"))) -> Até R$ 1 mi
A7: VND-006 | B7: Panamera 4 | C7: Panamera | D7: Sedã / GT | E7: Combustão | F7: 2023 | G7: Rio de Janeiro | H7: RJ | I7: Sudeste | J7: Cartão de crédito | K7: 1.4615 | L7: =ROUND(INDEX(Premissas!$C$6:$C$11,MATCH(C7,Premissas!$B$6:$B$11,0))*K7,-3) -> 1403000 | M7: =IF(L7<1000000,"Até R$ 1 mi",IF(L7<1500000,"R$ 1–1,5 mi",IF(L7<2000000,"R$ 1,5–2 mi","Acima de R$ 2 mi"))) -> R$ 1–1,5 mi
A8: VND-007 | B8: 911 Carrera S | C8: 911 | D8: Esportivo | E8: Combustão | F8: 2020 | G8: Porto Alegre | H8: RS | I8: Sul | J8: Leasing | K8: 1 | L8: =ROUND(INDEX(Premissas!$C$6:$C$11,MATCH(C8,Premissas!$B$6:$B$11,0))*K8,-3) -> 980000 | M8: =IF(L8<1000000,"Até R$ 1 mi",IF(L8<1500000,"R$ 1–1,5 mi",IF(L8<2000000,"R$ 1,5–2 mi","Acima de R$ 2 mi"))) -> Até R$ 1 mi
A9: VND-008 | B9: Cayenne E-Hybrid | C9: Cayenne | D9: SUV | E9: Híbrido | F9: 2022 | G9: Florianópolis | H9: SC | I9: Sul | J9: Pix | K9: 1.1686 | L9: =ROUND(INDEX(Premissas!$C$6:$C$11,MATCH(C9,Premissas!$B$6:$B$11,0))*K9,-3) -> 947000 | M9: =IF(L9<1000000,"Até R$ 1 mi",IF(L9<1500000,"R$ 1–1,5 mi",IF(L9<2000000,"R$ 1,5–2 mi","Acima de R$ 2 mi"))) -> Até R$ 1 mi
A10: VND-009 | B10: 718 Boxster | C10: 718 | D10: Esportivo | E10: Combustão | F10: 2021 | G10: Goiânia | H10: GO | I10: Centro-Oeste | J10: Cartão de débito | K10: 1.0515 | L10: =ROUND(INDEX(Premissas!$C$6:$C$11,MATCH(C10,Premissas!$B$6:$B$11,0))*K10,-3) -> 862000 | M10: =IF(L10<1000000,"Até R$ 1 mi",IF(L10<1500000,"R$ 1–1,5 mi",IF(L10<2000000,"R$ 1,5–2 mi","Acima de R$ 2 mi"))) -> Até R$ 1 mi
A11: VND-010 | B11: Macan GTS | C11: Macan | D11: SUV | E11: Combustão | F11: 2024 | G11: São Paulo | H11: SP | I11: Sudeste | J11: Financiamento | K11: 1.6129 | L11: =ROUND(INDEX(Premissas!$C$6:$C$11,MATCH(C11,Premissas!$B$6:$B$11,0))*K11,-3) -> 935000 | M11: =IF(L11<1000000,"Até R$ 1 mi",IF(L11<1500000,"R$ 1–1,5 mi",IF(L11<2000000,"R$ 1,5–2 mi","Acima de R$ 2 mi"))) -> Até R$ 1 mi
A12: VND-011 | B12: Taycan Turbo | C12: Taycan | D12: Sedã / GT | E12: Elétrico | F12: 2023 | G12: São Paulo | H12: SP | I12: Sudeste | J12: Boleto | K12: 1.3105 | L12: =ROUND(INDEX(Premissas!$C$6:$C$11,MATCH(C12,Premissas!$B$6:$B$11,0))*K12,-3) -> 1114000 | M12: =IF(L12<1000000,"Até R$ 1 mi",IF(L12<1500000,"R$ 1–1,5 mi",IF(L12<2000000,"R$ 1,5–2 mi","Acima de R$ 2 mi"))) -> R$ 1–1,5 mi
A13: VND-012 | B13: 911 GT3 | C13: 911 | D13: Esportivo | E13: Combustão | F13: 2024 | G13: Goiânia | H13: GO | I13: Centro-Oeste | J13: Pix | K13: 2.5026 | L13: =ROUND(INDEX(Premissas!$C$6:$C$11,MATCH(C13,Premissas!$B$6:$B$11,0))*K13,-3) -> 2453000 | M13: =IF(L13<1000000,"Até R$ 1 mi",IF(L13<1500000,"R$ 1–1,5 mi",IF(L13<2000000,"R$ 1,5–2 mi","Acima de R$ 2 mi"))) -> Acima de R$ 2 mi
... A101: VND-100 | B101: 911 Dakar | C101: 911 | D101: Esportivo | E101: Combustão | F101: 2024 | G101: Curitiba | H101: PR | I101: Sul | J101: Leasing | K101: 2.8214 | L101: =ROUND(INDEX(Premissas!$C$6:$C$11,MATCH(C101,Premissas!$B$6:$B$11,0))*K101,-3) -> 2765000 | M101: =IF(L101<1000000,"Até R$ 1 mi",IF(L101<1500000,"R$ 1–1,5 mi",IF(L101<2000000,"R$ 1,5–2 mi","Acima de R$ 2 mi"))) -> Acima de R$ 2 mi

Sheet Premissas
B2: Premissas de preço
B3: Preço público sugerido de entrada por linha, Brasil, fev/2026
B5: Linha | C5: Preço de entrada (R$) | D5: Segmento
B6: Macan | C6: 580000 | D6: SUV
B7: Cayenne | C7: 810000 | D7: SUV
B8: 718 | C8: 820000 | D8: Esportivo
B9: Taycan | C9: 850000 | D9: Sedã / GT
B10: Panamera | C10: 960000 | D10: Sedã / GT
B11: 911 | C11: 980000 | D11: Esportivo
B13: Fonte: Vrum / Estado de Minas, fev/2026 (link na aba Leia-me). Edite as células amarelas para simular outra tabela de preços.

Sheet Dicionário
B2: Dicionário de dados — aba Vendas
B4: Coluna | C4: Tipo | D4: Descrição / regra
B5: ID | C5: Texto | D5: Identificador único da venda (VND-001 a VND-100).
B6: Versão | C6: Texto | D6: Versão do modelo vendida, ex.: 911 Carrera S.
B7: Linha | C7: Texto | D7: Família do modelo: 911, 718, Taycan, Panamera, Cayenne, Macan.
B8: Segmento | C8: Texto | D8: Derivado da linha: Esportivo (911, 718), Sedã / GT (Taycan, Panamera), SUV (Cayenne, Macan).
B9: Propulsão | C9: Texto | D9: Derivado da versão: Elétrico (Taycan, Macan Electric), Híbrido (E-Hybrid), Combustão (demais).
B10: Ano | C10: Texto | D10: Ano da venda (2020–2026).
B11: Cidade | C11: Texto | D11: Cidade do Porsche Center que fez a venda.
B12: UF | C12: Texto | D12: Sigla do estado.
B13: Região | C13: Texto | D13: Região do IBGE.
B14: Forma de pagamento | C14: Texto | D14: Pix, TED, Boleto, Dinheiro, Cartão de crédito, Cartão de débito, Financiamento, Leasing, Criptomoeda.
B15: Fator de versão | C15: Número | D15: Preço da versão ÷ preço da versão mais barata da linha na tabela original.
... B17: Faixa de preço | C17: Texto | D17: Fórmula: Até R$ 1 mi · R$ 1–1,5 mi · R$ 1,5–2 mi · Acima de R$ 2 mi.
